Workbook

Sheet Start Here
A1: A household financial strategy simulator for Australians with property, super and mortgage complexity who want to test retirement and wealth decisions before speaking to an adviser. [Best-in-Class] Australian Financial Planning Workbook
A3: Single consolidated workbook: detailed budget, multi-property portfolio (PPOR + 3 IPs), scenario toggles, deterministic projections, Monte Carlo probability fan, and an executive dashboard with charts. All figures are dummy demo values—replace locally with your real numbers.
A5: How to use:
A6: 1) Use 'Control Centre' to set Active Scenario, Profile inputs and AU rules.
A7: 2) Enter your detailed monthly budget on 'Budget'.
A8: 3) Enter balances and cashflows on 'Assets & Liabilities', 'Superannuation (Inputs)', 'Properties'.
A9: 4) Review 'Projections' + 'Monte Carlo', then the 'Dashboard'.

Sheet Control Centre
A1: Control Centre | Household Profile + Scenarios + AU Rules
A3: Primary input sheet for the workbook. Update household profile, scenario assumptions and AU rule settings here. Legacy sheets remain as mirrors so existing model links keep working.
A5: Household Profile | F5: Scenario Matrix | P5: Active Scenario
A6: Item | B6: Value | C6: Notes | F6: Scenario | G6: Retire Age | H6: Return Mean | I6: Volatility | J6: Inflation | K6: Property Growth | L6: Rent Yield | M6: Rental Income Growth | N6: Partner Retire Age | P6: Active Scenario | Q6: Base
A7: Your Age | B7: 48 | F7: Base | G7: 60 | H7: 0.065 | I7: 0.11 | J7: 0.025 | K7: 0.045 | L7: 0.050164706 | M7: 0.03 | N7: 53 | P7: Retire Age | Q7: =IF($Q$6="Base",$G$7,IF($Q$6="Conservative",$G$8,$G$9)) -> 60
A8: Partner Age | B8: 41 | F8: Conservative | G8: 62 | H8: 0.055 | I8: 0.09 | J8: 0.03 | K8: 0.035 | L8: 0.038 | M8: 0.025 | N8: 55 | P8: Return Mean | Q8: =IF($Q$6="Base",$H$7,IF($Q$6="Conservative",$H$8,$H$9)) -> 0.065
A9: Life Expectancy | B9: 90 | F9: Aggressive | G9: 58 | H9: 0.075 | I9: 0.14 | J9: 0.02 | K9: 0.055 | L9: 0.042 | M9: 0.035 | N9: 51 | P9: Volatility | Q9: =IF($Q$6="Base",$I$7,IF($Q$6="Conservative",$I$8,$I$9)) -> 0.11
A10: Your Gross income (p.a.) | B10: 180000 | C10: TBC with a job | P10: Inflation | Q10: =IF($Q$6="Base",$J$7,IF($Q$6="Conservative",$J$8,$J$9)) -> 0.025
A11: Spouse Gross income (p.a.) | B11: 166000 | P11: Property Growth | Q11: =IF($Q$6="Base",$K$7,IF($Q$6="Conservative",$K$8,$K$9)) -> 0.045
A12: Spouse Gross income (p.a.) Y1 (2027) | B12: 172000 | F12: Rental Growth Rationale | P12: Rent Yield | Q12: =IF($Q$6="Base",$L$7,IF($Q$6="Conservative",$L$8,$L$9)) -> 0.050164706
A13: Target retirement spending (after tax, p.a.) | B13: 110000 | C13: Demo | F13: Scenario | G13: Rental Growth | H13: Rationale | P13: Rental Income Growth | Q13: =IF($Q$6="Base",$M$7,IF($Q$6="Conservative",$M$8,$M$9)) -> 0.03
A14: Kids | B14: 2 | F14: Conservative | G14: 0.025 | H14: Roughly long-run CPI | P14: Partner Retire Age | Q14: =IF($Q$6="Base",$N$7,IF($Q$6="Conservative",$N$8,$N$9)) -> 53
A15: Other assets (non-super, non-property) | B15: 50000 | C15: Demo | F15: Base | G15: 0.03 | H15: CPI + modest real growth
A16: Partner Years Younger | B16: 7 | F16: Aggressive | G16: 0.035 | H16: Tight rental market, wage pressure
A17: Your Retire Age (scenario-driven) | B17: already exists
A18: Partner Retire Age – Base | B18: 55 | F18: Inflation Rationale
A19: Partner Retire Age – Conservative | B19: 60 | F19: Scenario | G19: Inflation | H19: Why
A20: Partner Retire Age – Aggressive | B20: 53 | F20: Scenario | G20: Inflation | H20: Why
A21: You Retirement Date Offset (FY) | B21: 0 | F21: Conservative | G21: 0.03 | H21: Higher cost pressure, stagflation risk | K21: Task (including Persona and Format), Context, References, Evaluate, and Iterate.
A22: Spouse Retirement Date Offset (FY) | B22: 0 | F22: Base | G22: 0.025 | H22: RBA midpoint, long-run normal
A24: AU Rules
A25: Rule | B25: Value | C25: Notes
A26: Super concessional cap | B26: 27500 | C26: Update for current FY
A27: Super tax rate (contrib/earnings) | B27: 0.15 | C27: Typical concessional tax
A28: Preservation age | B28: 60 | C28: Depends on DOB; common for many cohorts
A29: Medicare levy (base) | B29: 0.02 | C29: Approx
A30: Safe withdrawal rate | B30: 0.04 | C30: Rule-of-thumb baseline

Sheet Profile
A1: Household Profile (Inputs)
A3: Legacy mirror sheet. Primary edits now happen on 'Control Centre'. This sheet remains to preserve workbook links.
A5: Item | B5: Value | C5: Notes | E5: Derived
A6: Your Age | B6: ='Control Centre'!$B$7 -> 48 | E6: Active Retire Age | F6: =Scenarios!K7 -> 60
A7: Partner Age | B7: ='Control Centre'!$B$8 -> 41 | E7: Years to Retire | F7: =F6-INDEX(B:B,MATCH("Your Age",A:A,0)) -> 12
A8: Life Expectancy | B8: ='Control Centre'!$B$9 -> 90
A9: Your Gross income (p.a.) | B9: ='Control Centre'!$B$10 -> 180000 | C9: TBC with a job | E9: Active Spouse Retire Age | F9: =Scenarios!K15 -> 53
A10: Spouse Gross income (p.a.) | B10: ='Control Centre'!$B$11 -> 166000
A11: Spouse Gross income (p.a.) Y1 (2027) | B11: ='Control Centre'!$B$12 -> 172000
A12: Target retirement spending (after tax, p.a.) | B12: ='Control Centre'!$B$13 -> 110000 | C12: Demo
A13: Kids | B13: ='Control Centre'!$B$14 -> 2
A14: Other assets (non-super, non-property) | B14: ='Control Centre'!$B$15 -> 50000 | C14: Demo
A15: Partner Years Younger | B15: ='Control Centre'!$B$16 -> 7
A16: Your Retire Age (scenario-driven) | B16: ='Control Centre'!$B$17 -> already exists
A17: Partner Retire Age – Base | B17: ='Control Centre'!$B$18 -> 55
A18: Partner Retire Age – Conservative | B18: ='Control Centre'!$B$19 -> 60
A19: Partner Retire Age – Aggressive | B19: ='Control Centre'!$B$20 -> 53
A20: You Retirement Date Offset (FY) | B20: ='Control Centre'!$B$21 -> 0
A21: Spouse Retirement Date Offset (FY) | B21: ='Control Centre'!$B$22 -> 0

Sheet AU Rules
A1: Australian Super & Tax Scaffold
A3: Legacy mirror sheet. Primary edits now happen on 'Control Centre'. This sheet remains to preserve workbook links.
A5: Rule | B5: Value | C5: Notes
A6: ='Control Centre'!$A$26 -> Super concessional cap | B6: ='Control Centre'!$B$26 -> 27500 | C6: ='Control Centre'!$C$26 -> Update for current FY
A7: ='Control Centre'!$A$27 -> Super tax rate (contrib/earnings) | B7: ='Control Centre'!$B$27 -> 0.15 | C7: ='Control Centre'!$C$27 -> Typical concessional tax
A8: ='Control Centre'!$A$28 -> Preservation age | B8: ='Control Centre'!$B$28 -> 60 | C8: ='Control Centre'!$C$28 -> Depends on DOB; common for many cohorts
A9: ='Control Centre'!$A$29 -> Medicare levy (base) | B9: ='Control Centre'!$B$29 -> 0.02 | C9: ='Control Centre'!$C$29 -> Approx
A10: ='Control Centre'!$A$30 -> Safe withdrawal rate | B10: ='Control Centre'!$B$30 -> 0.04 | C10: ='Control Centre'!$C$30 -> Rule-of-thumb baseline

Sheet Scenarios
A1: Scenario Control
A3: Legacy mirror sheet. Primary edits now happen on 'Control Centre'. This sheet remains to preserve workbook links.
J4: Active Scenario
J5: ='Control Centre'!$Q$6 -> Base
A6: Scenario | B6: Retire Age | C6: Return Mean | D6: Volatility | E6: Inflation | F6: Property Growth | G6: Rent Yield | H6: Rental Income Growth | I6: Partner Retire Age | J6: Notes
A7: ='Control Centre'!$F$7 -> Base | B7: ='Control Centre'!$G$7 -> 60 | C7: ='Control Centre'!$H$7 -> 0.065 | D7: ='Control Centre'!$I$7 -> 0.11 | E7: ='Control Centre'!$J$7 -> 0.025 | F7: ='Control Centre'!$K$7 -> 0.045 | G7: ='Control Centre'!$L$7 -> 0.050164706 | H7: ='Control Centre'!$M$7 -> 0.03 | I7: ='Control Centre'!$N$7 -> 53 | J7: Active Retire Age | K7: ='Control Centre'!$Q$7 -> 60
A8: ='Control Centre'!$F$8 -> Conservative | B8: ='Control Centre'!$G$8 -> 62 | C8: ='Control Centre'!$H$8 -> 0.055 | D8: ='Control Centre'!$I$8 -> 0.09 | E8: ='Control Centre'!$J$8 -> 0.03 | F8: ='Control Centre'!$K$8 -> 0.035 | G8: ='Control Centre'!$L$8 -> 0.038 | H8: ='Control Centre'!$M$8 -> 0.025 | I8: ='Control Centre'!$N$8 -> 55 | J8: Active Return Mean | K8: ='Control Centre'!$Q$8 -> 0.065
A9: ='Control Centre'!$F$9 -> Aggressive | B9: ='Control Centre'!$G$9 -> 58 | C9: ='Control Centre'!$H$9 -> 0.075 | D9: ='Control Centre'!$I$9 -> 0.14 | E9: ='Control Centre'!$J$9 -> 0.02 | F9: ='Control Centre'!$K$9 -> 0.055 | G9: ='Control Centre'!$L$9 -> 0.042 | H9: ='Control Centre'!$M$9 -> 0.035 | I9: ='Control Centre'!$N$9 -> 51 | J9: Active Volatility | K9: ='Control Centre'!$Q$9 -> 0.11
J10: Active Inflation | K10: ='Control Centre'!$Q$10 -> 0.025
J11: Property Growth | K11: ='Control Centre'!$Q$11 -> 0.045
J12: Rent Yield | K12: ='Control Centre'!$Q$12 -> 0.050164706
A13: Rental Income Growth | J13: Active Rental Income Growth | K13: ='Control Centre'!$Q$13 -> 0.03
A14: Scenario | B14: Rental Growth | C14: Rationale
A15: ='Control Centre'!$F$14 -> Conservative | B15: ='Control Centre'!$G$14 -> 0.025 | C15: ='Control Centre'!$H$14 -> Roughly long-run CPI | J15: Active Spouse Retire Age | K15: ='Control Centre'!$Q$14 -> 53
A16: ='Control Centre'!$F$15 -> Base | B16: ='Control Centre'!$G$15 -> 0.03 | C16: ='Control Centre'!$H$15 -> CPI + modest real growth
A17: ='Control Centre'!$F$16 -> Aggressive | B17: ='Control Centre'!$G$16 -> 0.035 | C17: ='Control Centre'!$H$16 -> Tight rental market, wage pressure
A20: Sanity check vs your existing assumptions
A22: You currently have:
A23: Property Growth: 4.5%
A24: Inflation: (likely ~2.5–3.0%)
A25: That gives:
A26: Capital growth > rental growth ✔
A27: Rental growth ≥ inflation ✔
A28: Yield slowly compresses over time ✔ (realistic)
A29: This passes an adviser / bank sniff test immediately.
A32: Recommended Inflation Assumptions
A34: ='Control Centre'!$F$20 -> Scenario | B34: ='Control Centre'!$G$20 -> Inflation | C34: ='Control Centre'!$H$20 -> Why
A35: ='Control Centre'!$F$21 -> Conservative | B35: ='Control Centre'!$G$21 -> 0.03 | C35: ='Control Centre'!$H$21 -> Higher cost pressure, stagflation risk
A36: ='Control Centre'!$F$22 -> Base | B36: ='Control Centre'!$G$22 -> 0.025 | C36: ='Control Centre'!$H$22 -> RBA midpoint, long-run normal
A37: Aggressive | B37: 0.02 | C37: Productivity gains, benign inflation

Sheet Projections
B1: Projections (Deterministic, Annual)
P2: =P7-F7-E7 -> 53451.23
B3: Projects total net worth and post-retirement spend-down.
A5: Year | B5: Year | C5: Age You | D5: Spouse Age | E5: Earned Income You | F5: Earned Income Spouse (Base) | G5: Super Contribution – You | H5: Super Tax - You | I5: Super Contribution - Spouse | J5: Super Tax - Spouse | K5: Super Balance - You | L5: Super Balance - Spouse | M5: Total Super | N5: Tax You | O5: Tax Spouse | P5: Total Earned Income | Q5: Living Budget (Annual) | R5: Net Rental (After Tax) | S5: Net Household Cashflow (Pre-Retire) | T5: Annual Surplus (Pre-Retirement) | U5: Super | V5: Property Equity | W5: Other Assets | X5: Total Net Worth | Y5: Spend (post-retire) | Z5: After Spend
A6: =ROW()-ROW($A$6)+1 -> 1 | B6: 2026 | C6: =Profile!B6 -> 48 | D6: =Profile!B7 -> 41 | E6: =IF( $C6 < Scenarios!$K$7, _xlfn.XLOOKUP($B6,'Income Schedule'!$A$5:$A$60,'Income Schedule'!$B$5:$B$60,0), IF( $C6 = Scenarios!$K$7, _xlfn.XLOOKUP($B6,'Income Schedule'!$A$5:$A$60,'Income Schedule'!$B$5:$B$60,0) * (1-Profile!$B$20), 0 ) ) -> 45000 | F6: =IF( $C6 < (Scenarios!$K$15 + (Profile!$B$6-Profile!$B$7)), _xlfn.XLOOKUP($B6,'Income Schedule'!$A$5:$A$60,'Income Schedule'!$C$5:$C$60,0), IF( $C6 = (Scenarios!$K$15 + (Profile!$B$6-Profile!$B$7)), _xlfn.XLOOKUP($B6,'Income Schedule'!$A$5:$A$60,'Income Schedule'!$C$5:$C$60,0) * (1-Profile!$B$21), 0 ) ) -> 166000 | G6: =IF( $C6 < Scenarios!$K$7, IF('Superannuation (Inputs)'!$I$6="Fixed", 'Superannuation (Inputs)'!$C$6, 'Superannuation (Inputs)'!$J$6 ), IF( $C6 = Scenarios!$K$7, IF('Superannuation (Inputs)'!$I$6="Fixed", 'Superannuation (Inputs)'!$C$6*(1-Profile!$B$20), 'Superannuation (Inputs)'!$J$6 ), 0 ) ) -> 5400 | H6: =G6 * 'Superannuation (Inputs)'!$H$6 -> 810 | I6: =IF( $C6 < (Scenarios!$K$15 + (Profile!$B$6-Profile!$B$7)), IF('Superannuation (Inputs)'!$I$7="Fixed", 'Superannuation (Inputs)'!$C$7, 'Superannuation (Inputs)'!$J$7 ), IF( $C6 = (Scenarios!$K$15 + (Profile!$B$6-Profile!$B$7)), IF('Superannuation (Inputs)'!$I$7="Fixed", 'Superannuation (Inputs)'!$C$7*(1-Profile!$B$21), 'Superannuation (Inputs)'!$J$7 ), 0 ) ) -> 25564 | J6: =I6 * 'Superannuation (Inputs)'!$H$7 -> 3834.6 | K6: ='Superannuation (Inputs)'!$B$6 -> 636000 | L6: ='Superannuation (Inputs)'!$B$7 -> 452000 | M6: =K6+L6 -> 1088000 | N6: =(IF((E6 + 0.5*INDEX(Property_CF!$B$187:$AZ$187,1,$A6))<=18200,0, IF((E6 + 0.5*INDEX(Property_CF!$B$187:$AZ$187,1,$A6))<=45000,((E6 + 0.5*INDEX(Property_CF!$B$187:$AZ$187,1,$A6))-18200)*0.19, IF((E6 + 0.5*INDEX(Property_CF!$B$187:$AZ$187,1,$A6))<=120000,5092+((E6 + 0.5*INDEX(Property_CF!$B$187:$AZ$187,1,$A6))-45000)*0.325, IF((E6 + 0.5*INDEX(Property_CF!$B$187:$AZ$187,1,$A6))<=180000,29467+((E6 + 0.5*INDEX(Property_CF!$B$187:$AZ$187,1,$A6))-120000)*0.37, 51667+((E6 + 0.5*INDEX(Property_CF!$B$187:$AZ$187,1,$A6))-180000)*0.45)))))+((E6 + 0.5*INDEX(Property_CF!$B$187:$AZ$187,1,$A6)))*0.02 -> 5992 | O6: =(IF((F6 + 0.5*INDEX(Property_CF!$B$187:$AZ$187,1,$A6))<=18200,0, IF((F6 + 0.5*INDEX(Property_CF!$B$187:$AZ$187,1,$A6))<=45000,((F6 + 0.5*INDEX(Property_CF!$B$187:$AZ$187,1,$A6))-18200)*0.19, IF((F6 + 0.5*INDEX(Property_CF!$B$187:$AZ$187,1,$A6))<=120000,5092+((F6 + 0.5*INDEX(Property_CF!$B$187:$AZ$187,1,$A6))-45000)*0.325, IF((F6 + 0.5*INDEX(Property_CF!$B$187:$AZ$187,1,$A6))<=180000,29467+((F6 + 0.5*INDEX(Property_CF!$B$187:$AZ$187,1,$A6))-120000)*0.37, 51667+((F6 + 0.5*INDEX(Property_CF!$B$187:$AZ$187,1,$A6))-180000)*0.45)))))+((F6 + 0.5*INDEX(Property_CF!$B$187:$AZ$187,1,$A6)))*0.02 -> 49807 | P6: {=E6+F6+INDEX(Property_CF!$C$187:$AZ$187,1,$A6)} -> 258859.68 | Q6: =Budget!$P$6 -> 76477.3 | R6: =SUM('Rental Tax & Gearing'!$H$6:$H$8) -> -11228.788 | S6: =IF($C6 < Scenarios!$K$7, (P6 + R6 - Q6), 0 ) -> 171153.59 | T6: =IF($C6 < Scenarios!$K$7, P6 - Budget!$P$6, 0) -> 182382.38 | U6: ='Superannuation (Inputs)'!N6 -> 1088000 | V6: =Properties!M8 -> 1683071.9 | W6: =Profile!B14 + 'Assets & Liabilities'!G8 -> 353316.06 | X6: =SUM(U6:W6) -> 3124388 | Y6: =IF(C6>=Scenarios!$K$7, Profile!B9*(1+Scenarios!$K$10)^(C6-Scenarios!$K$7), 0) -> 0 | Z6: =X6-Y6 -> 3124388
A7: =ROW()-ROW($A$6)+1 -> 2 | B7: =B6+1 -> 2027 | C7: =C6+1 -> 49 | D7: =D6+1 -> 42 | E7: =IF( $C7 < Scenarios!$K$7, _xlfn.XLOOKUP($B7,'Income Schedule'!$A$5:$A$60,'Income Schedule'!$B$5:$B$60,0), IF( $C7 = Scenarios!$K$7, _xlfn.XLOOKUP($B7,'Income Schedule'!$A$5:$A$60,'Income Schedule'!$B$5:$B$60,0) * (1-Profile!$B$20), 0 ) ) -> 180000 | F7: =IF( $C7 < (Scenarios!$K$15 + (Profile!$B$6-Profile!$B$7)), _xlfn.XLOOKUP($B7,'Income Schedule'!$A$5:$A$60,'Income Schedule'!$C$5:$C$60,0), IF( $C7 = (Scenarios!$K$15 + (Profile!$B$6-Profile!$B$7)), _xlfn.XLOOKUP($B7,'Income Schedule'!$A$5:$A$60,'Income Schedule'!$C$5:$C$60,0) * (1-Profile!$B$21), 0 ) ) -> 172000 | G7: =IF( $C7 < Scenarios!$K$7, IF('Superannuation (Inputs)'!$I$6="Fixed", 'Superannuation (Inputs)'!$C$6, 'Superannuation (Inputs)'!$J$6 ), IF( $C7 = Scenarios!$K$7, IF('Superannuation (Inputs)'!$I$6="Fixed", 'Superannuation (Inputs)'!$C$6*(1-Profile!$B$20), 'Superannuation (Inputs)'!$J$6 ), 0 ) ) -> 5400 | H7: =G7 * 'Superannuation (Inputs)'!$H$6 -> 810 | I7: =IF( $C7 < (Scenarios!$K$15 + (Profile!$B$6-Profile!$B$7)), IF('Superannuation (Inputs)'!$I$7="Fixed", 'Superannuation (Inputs)'!$C$7, 'Superannuation (Inputs)'!$J$7 ), IF( $C7 = (Scenarios!$K$15 + (Profile!$B$6-Profile!$B$7)), IF('Superannuation (Inputs)'!$I$7="Fixed", 'Superannuation (Inputs)'!$C$7*(1-Profile!$B$21), 'Superannuation (Inputs)'!$J$7 ), 0 ) ) -> 25564 | J7: =I7 * 'Superannuation (Inputs)'!$H$7 -> 3834.6 | K7: =K6*(1+Scenarios!$K$8) + G7-H7 -> 681930 | L7: =L6*(1+Scenarios!$K$8) + H7-I7 -> 456626 | M7: =K7+L7 -> 1138556 | N7: =(IF((E7 + 0.5*INDEX(Property_CF!$B$187:$AZ$187,1,$A7))<=18200,0, IF((E7 + 0.5*INDEX(Property_CF!$B$187:$AZ$187,1,$A7))<=45000,((E7 + 0.5*INDEX(Property_CF!$B$187:$AZ$187,1,$A7))-18200)*0.19, IF((E7 + 0.5*INDEX(Property_CF!$B$187:$AZ$187,1,$A7))<=120000,5092+((E7 + 0.5*INDEX(Property_CF!$B$187:$AZ$187,1,$A7))-45000)*0.325, IF((E7 + 0.5*INDEX(Property_CF!$B$187:$AZ$187,1,$A7))<=180000,29467+((E7 + 0.5*INDEX(Property_CF!$B$187:$AZ$187,1,$A7))-120000)*0.37, 51667+((E7 + 0.5*INDEX(Property_CF!$B$187:$AZ$187,1,$A7))-180000)*0.45)))))+((E7 + 0.5*INDEX(Property_CF!$B$187:$AZ$187,1,$A7)))*0.02 -> 66514.024 | O7: =(IF((F7 + 0.5*INDEX(Property_CF!$B$187:$AZ$187,1,$A7))<=18200,0, IF((F7 + 0.5*INDEX(Property_CF!$B$187:$AZ$187,1,$A7))<=45000,((F7 + 0.5*INDEX(Property_CF!$B$187:$AZ$187,1,$A7))-18200)*0.19, IF((F7 + 0.5*INDEX(Property_CF!$B$187:$AZ$187,1,$A7))<=120000,5092+((F7 + 0.5*INDEX(Property_CF!$B$187:$AZ$187,1,$A7))-45000)*0.325, IF((F7 + 0.5*INDEX(Property_CF!$B$187:$AZ$187,1,$A7))<=180000,29467+((F7 + 0.5*INDEX(Property_CF!$B$187:$AZ$187,1,$A7))-120000)*0.37, 51667+((F7 + 0.5*INDEX(Property_CF!$B$187:$AZ$187,1,$A7))-180000)*0.45)))))+((F7 + 0.5*INDEX(Property_CF!$B$187:$AZ$187,1,$A7)))*0.02 -> 62754.024 | P7: {=E7+F7+INDEX(Property_CF!$C$187:$AZ$187,1,$A7)} -> 405451.23 | Q7: =Budget!$P$6 -> 76477.3 | R7: =SUM('Rental Tax & Gearing'!$H$6:$H$8) -> -11228.788 | S7: =IF($C7 < Scenarios!$K$7, (P7 + R7 - Q7), 0 ) -> 317745.14 | T7: =IF($C7 < Scenarios!$K$7, P7 - Budget!$P$6, 0) -> 328973.93 | U7: =U6*(1+Scenarios!$K$8) + IF(C7<Scenarios!$K$7, 'Superannuation (Inputs)'!$N$7, 0) -> 1213720 | V7: =V6*(1+Scenarios!$K$11) -> 1758810.1 | W7: =W6*(1+Scenarios!$K$8) + S7 -> 694026.75 | X7: =SUM(U7:W7) -> 3666556.9 | Y7: =IF(C7>=Scenarios!$K$7, Profile!B10*(1+Scenarios!$K$10)^(C7-Scenarios!$K$7), 0) -> 0 | Z7: =X7-Y7 -> 3666556.9
A8: =ROW()-ROW($A$6)+1 -> 3 | B8: =B7+1 -> 2028 | C8: =C7+1 -> 50 | D8: =D7+1 -> 43 | E8: =IF( $C8 < Scenarios!$K$7, _xlfn.XLOOKUP($B8,'Income Schedule'!$A$5:$A$60,'Income Schedule'!$B$5:$B$60,0), IF( $C8 = Scenarios!$K$7, _xlfn.XLOOKUP($B8,'Income Schedule'!$A$5:$A$60,'Income Schedule'!$B$5:$B$60,0) * (1-Profile!$B$20), 0 ) ) -> 180000 | F8: =IF( $C8 < (Scenarios!$K$15 + (Profile!$B$6-Profile!$B$7)), _xlfn.XLOOKUP($B8,'Income Schedule'!$A$5:$A$60,'Income Schedule'!$C$5:$C$60,0), IF( $C8 = (Scenarios!$K$15 + (Profile!$B$6-Profile!$B$7)), _xlfn.XLOOKUP($B8,'Income Schedule'!$A$5:$A$60,'Income Schedule'!$C$5:$C$60,0) * (1-Profile!$B$21), 0 ) ) -> 172000 | G8: =IF( $C8 < Scenarios!$K$7, IF('Superannuation (Inputs)'!$I$6="Fixed", 'Superannuation (Inputs)'!$C$6, 'Superannuation (Inputs)'!$J$6 ), IF( $C8 = Scenarios!$K$7, IF('Superannuation (Inputs)'!$I$6="Fixed", 'Superannuation (Inputs)'!$C$6*(1-Profile!$B$20), 'Superannuation (Inputs)'!$J$6 ), 0 ) ) -> 5400 | H8: =G8 * 'Superannuation (Inputs)'!$H$6 -> 810 | I8: =IF( $C8 < (Scenarios!$K$15 + (Profile!$B$6-Profile!$B$7)), IF('Superannuation (Inputs)'!$I$7="Fixed", 'Superannuation (Inputs)'!$C$7, 'Superannuation (Inputs)'!$J$7 ), IF( $C8 = (Scenarios!$K$15 + (Profile!$B$6-Profile!$B$7)), IF('Superannuation (Inputs)'!$I$7="Fixed", 'Superannuation (Inputs)'!$C$7*(1-Profile!$B$21), 'Superannuation (Inputs)'!$J$7 ), 0 ) ) -> 25564 | J8: =I8 * 'Superannuation (Inputs)'!$H$7 -> 3834.6 | K8: =K7*(1+Scenarios!$K$8) + G8-H8 -> 730845.45 | L8: =L7*(1+Scenarios!$K$8) + H8-I8 -> 461552.69 | M8: =K8+L8 -> 1192398.1 | N8: =(IF((E8 + 0.5*INDEX(Property_CF!$B$187:$AZ$187,1,$A8))<=18200,0, IF((E8 + 0.5*INDEX(Property_CF!$B$187:$AZ$187,1,$A8))<=45000,((E8 + 0.5*INDEX(Property_CF!$B$187:$AZ$187,1,$A8))-18200)*0.19, IF((E8 + 0.5*INDEX(Property_CF!$B$187:$AZ$187,1,$A8))<=120000,5092+((E8 + 0.5*INDEX(Property_CF!$B$187:$AZ$187,1,$A8))-45000)*0.325, IF((E8 + 0.5*INDEX(Property_CF!$B$187:$AZ$187,1,$A8))<=180000,29467+((E8 + 0.5*INDEX(Property_CF!$B$187:$AZ$187,1,$A8))-120000)*0.37, 51667+((E8 + 0.5*INDEX(Property_CF!$B$187:$AZ$187,1,$A8))-180000)*0.45)))))+((E8 + 0.5*INDEX(Property_CF!$B$187:$AZ$187,1,$A8)))*0.02 -> 67828.039 | O8: =(IF((F8 + 0.5*INDEX(Property_CF!$B$187:$AZ$187,1,$A8))<=18200,0, IF((F8 + 0.5*INDEX(Property_CF!$B$187:$AZ$187,1,$A8))<=45000,((F8 + 0.5*INDEX(Property_CF!$B$187:$AZ$187,1,$A8))-18200)*0.19, IF((F8 + 0.5*INDEX(Property_CF!$B$187:$AZ$187,1,$A8))<=120000,5092+((F8 + 0.5*INDEX(Property_CF!$B$187:$AZ$187,1,$A8))-45000)*0.325, IF((F8 + 0.5*INDEX(Property_CF!$B$187:$AZ$187,1,$A8))<=180000,29467+((F8 + 0.5*INDEX(Property_CF!$B$187:$AZ$187,1,$A8))-120000)*0.37, 51667+((F8 + 0.5*INDEX(Property_CF!$B$187:$AZ$187,1,$A8))-180000)*0.45)))))+((F8 + 0.5*INDEX(Property_CF!$B$187:$AZ$187,1,$A8)))*0.02 -> 64068.039 | P8: {=E8+F8+INDEX(Property_CF!$C$187:$AZ$187,1,$A8)} -> 408419.18 | Q8: =Budget!$P$6 -> 76477.3 | R8: =SUM('Rental Tax & Gearing'!$H$6:$H$8) -> -11228.788 | S8: =IF($C8 < Scenarios!$K$7, (P8 + R8 - Q8), 0 ) -> 320713.09 | T8: =IF($C8 < Scenarios!$K$7, P8 - Budget!$P$6, 0) -> 331941.88 | U8: =U7*(1+Scenarios!$K$8) + IF(C8<Scenarios!$K$7, 'Superannuation (Inputs)'!$N$7, 0) -> 1347611.8 | V8: =V7*(1+Scenarios!$K$11) -> 1837956.6 | W8: =W7*(1+0.03) -> 714847.55 | X8: =SUM(U8:W8) -> 3900416 | Y8: =IF(C8>=Scenarios!$K$7, Profile!B11*(1+Scenarios!$K$10)^(C8-Scenarios!$K$7), 0) -> 0 | Z8: =X8-Y8 -> 3900416
A9: =ROW()-ROW($A$6)+1 -> 4 | B9: =B8+1 -> 2029 | C9: =C8+1 -> 51 | D9: =D8+1 -> 44 | E9: =IF( $C9 < Scenarios!$K$7, _xlfn.XLOOKUP($B9,'Income Schedule'!$A$5:$A$60,'Income Schedule'!$B$5:$B$60,0), IF( $C9 = Scenarios!$K$7, _xlfn.XLOOKUP($B9,'Income Schedule'!$A$5:$A$60,'Income Schedule'!$B$5:$B$60,0) * (1-Profile!$B$20), 0 ) ) -> 180000 | F9: =IF( $C9 < (Scenarios!$K$15 + (Profile!$B$6-Profile!$B$7)), _xlfn.XLOOKUP($B9,'Income Schedule'!$A$5:$A$60,'Income Schedule'!$C$5:$C$60,0), IF( $C9 = (Scenarios!$K$15 + (Profile!$B$6-Profile!$B$7)), _xlfn.XLOOKUP($B9,'Income Schedule'!$A$5:$A$60,'Income Schedule'!$C$5:$C$60,0) * (1-Profile!$B$21), 0 ) ) -> 172000 | G9: =IF( $C9 < Scenarios!$K$7, IF('Superannuation (Inputs)'!$I$6="Fixed", 'Superannuation (Inputs)'!$C$6, 'Superannuation (Inputs)'!$J$6 ), IF( $C9 = Scenarios!$K$7, IF('Superannuation (Inputs)'!$I$6="Fixed", 'Superannuation (Inputs)'!$C$6*(1-Profile!$B$20), 'Superannuation (Inputs)'!$J$6 ), 0 ) ) -> 5400 | H9: =G9 * 'Superannuation (Inputs)'!$H$6 -> 810 | I9: =IF( $C9 < (Scenarios!$K$15 + (Profile!$B$6-Profile!$B$7)), IF('Superannuation (Inputs)'!$I$7="Fixed", 'Superannuation (Inputs)'!$C$7, 'Superannuation (Inputs)'!$J$7 ), IF( $C9 = (Scenarios!$K$15 + (Profile!$B$6-Profile!$B$7)), IF('Superannuation (Inputs)'!$I$7="Fixed", 'Superannuation (Inputs)'!$C$7*(1-Profile!$B$21), 'Superannuation (Inputs)'!$J$7 ), 0 ) ) -> 25564 | J9: =I9 * 'Superannuation (Inputs)'!$H$7 -> 3834.6 | K9: =K8*(1+Scenarios!$K$8) + G9-H9 -> 782940.4 | L9: =L8*(1+Scenarios!$K$8) + H9-I9 -> 466799.61 | M9: =K9+L9 -> 1249740 | N9: =(IF((E9 + 0.5*INDEX(Property_CF!$B$187:$AZ$187,1,$A9))<=18200,0, IF((E9 + 0.5*INDEX(Property_CF!$B$187:$AZ$187,1,$A9))<=45000,((E9 + 0.5*INDEX(Property_CF!$B$187:$AZ$187,1,$A9))-18200)*0.19, IF((E9 + 0.5*INDEX(Property_CF!$B$187:$AZ$187,1,$A9))<=120000,5092+((E9 + 0.5*INDEX(Property_CF!$B$187:$AZ$187,1,$A9))-45000)*0.325, IF((E9 + 0.5*INDEX(Property_CF!$B$187:$AZ$187,1,$A9))<=180000,29467+((E9 + 0.5*INDEX(Property_CF!$B$187:$AZ$187,1,$A9))-120000)*0.37, 51667+((E9 + 0.5*INDEX(Property_CF!$B$187:$AZ$187,1,$A9))-180000)*0.45)))))+((E9 + 0.5*INDEX(Property_CF!$B$187:$AZ$187,1,$A9)))*0.02 -> 68525.507 | O9: =(IF((F9 + 0.5*INDEX(Property_CF!$B$187:$AZ$187,1,$A9))<=18200,0, IF((F9 + 0.5*INDEX(Property_CF!$B$187:$AZ$187,1,$A9))<=45000,((F9 + 0.5*INDEX(Property_CF!$B$187:$AZ$187,1,$A9))-18200)*0.19, IF((F9 + 0.5*INDEX(Property_CF!$B$187:$AZ$187,1,$A9))<=120000,5092+((F9 + 0.5*INDEX(Property_CF!$B$187:$AZ$187,1,$A9))-45000)*0.325, IF((F9 + 0.5*INDEX(Property_CF!$B$187:$AZ$187,1,$A9))<=180000,29467+((F9 + 0.5*INDEX(Property_CF!$B$187:$AZ$187,1,$A9))-120000)*0.37, 51667+((F9 + 0.5*INDEX(Property_CF!$B$187:$AZ$187,1,$A9))-180000)*0.45)))))+((F9 + 0.5*INDEX(Property_CF!$B$187:$AZ$187,1,$A9)))*0.02 -> 64765.507 | P9: {=E9+F9+INDEX(Property_CF!$C$187:$AZ$187,1,$A9)} -> 411476.22 | Q9: =Budget!$P$6 -> 76477.3 | R9: =SUM('Rental Tax & Gearing'!$H$6:$H$8) -> -11228.788 | S9: =IF($C9 < Scenarios!$K$7, (P9 + R9 - Q9), 0 ) -> 323770.14 | T9: =IF($C9 < Scenarios!$K$7, P9 - Budget!$P$6, 0) -> 334998.92 | U9: =U8*(1+Scenarios!$K$8) + IF(C9<Scenarios!$K$7, 'Superannuation (Inputs)'!$N$7, 0) -> 1490206.6 | V9: =V8*(1+Scenarios!$K$11) -> 1920664.6 | W9: =W8*(1+0.03) -> 736292.98 | X9: =SUM(U9:W9) -> 4147164.2 | Y9: =IF(C9>=Scenarios!$K$7, Profile!B12*(1+Scenarios!$K$10)^(C9-Scenarios!$K$7), 0) -> 0 | Z9: =X9-Y9 -> 4147164.2
A10: =ROW()-ROW($A$6)+1 -> 5 | B10: =B9+1 -> 2030 | C10: =C9+1 -> 52 | D10: =D9+1 -> 45 | E10: =IF( $C10 < Scenarios!$K$7, _xlfn.XLOOKUP($B10,'Income Schedule'!$A$5:$A$60,'Income Schedule'!$B$5:$B$60,0), IF( $C10 = Scenarios!$K$7, _xlfn.XLOOKUP($B10,'Income Schedule'!$A$5:$A$60,'Income Schedule'!$B$5:$B$60,0) * (1-Profile!$B$20), 0 ) ) -> 180000 | F10: =IF( $C10 < (Scenarios!$K$15 + (Profile!$B$6-Profile!$B$7)), _xlfn.XLOOKUP($B10,'Income Schedule'!$A$5:$A$60,'Income Schedule'!$C$5:$C$60,0), IF( $C10 = (Scenarios!$K$15 + (Profile!$B$6-Profile!$B$7)), _xlfn.XLOOKUP($B10,'Income Schedule'!$A$5:$A$60,'Income Schedule'!$C$5:$C$60,0) * (1-Profile!$B$21), 0 ) ) -> 172000 | G10: =IF( $C10 < Scenarios!$K$7, IF('Superannuation (Inputs)'!$I$6="Fixed", 'Superannuation (Inputs)'!$C$6, 'Superannuation (Inputs)'!$J$6 ), IF( $C10 = Scenarios!$K$7, IF('Superannuation (Inputs)'!$I$6="Fixed", 'Superannuation (Inputs)'!$C$6*(1-Profile!$B$20), 'Superannuation (Inputs)'!$J$6 ), 0 ) ) -> 5400 | H10: =G10 * 'Superannuation (Inputs)'!$H$6 -> 810 | I10: =IF( $C10 < (Scenarios!$K$15 + (Profile!$B$6-Profile!$B$7)), IF('Superannuation (Inputs)'!$I$7="Fixed", 'Superannuation (Inputs)'!$C$7, 'Superannuation (Inputs)'!$J$7 ), IF( $C10 = (Scenarios!$K$15 + (Profile!$B$6-Profile!$B$7)), IF('Superannuation (Inputs)'!$I$7="Fixed", 'Superannuation (Inputs)'!$C$7*(1-Profile!$B$21), 'Superannuation (Inputs)'!$J$7 ), 0 ) ) -> 25564 | J10: =I10 * 'Superannuation (Inputs)'!$H$7 -> 3834.6 | K10: =K9*(1+Scenarios!$K$8) + G10-H10 -> 838421.53 | L10: =L9*(1+Scenarios!$K$8) + H10-I10 -> 472387.59 | M10: =K10+L10 -> 1310809.1 | N10: =(IF((E10 + 0.5*INDEX(Property_CF!$B$187:$AZ$187,1,$A10))<=18200,0, IF((E10 + 0.5*INDEX(Property_CF!$B$187:$AZ$187,1,$A10))<=45000,((E10 + 0.5*INDEX(Property_CF!$B$187:$AZ$187,1,$A10))-18200)*0.19, IF((E10 + 0.5*INDEX(Property_CF!$B$187:$AZ$187,1,$A10))<=120000,5092+((E10 + 0.5*INDEX(Property_CF!$B$187:$AZ$187,1,$A10))-45000)*0.325, IF((E10 + 0.5*INDEX(Property_CF!$B$187:$AZ$187,1,$A10))<=180000,29467+((E10 + 0.5*INDEX(Property_CF!$B$187:$AZ$187,1,$A10))-120000)*0.37, 51667+((E10 + 0.5*INDEX(Property_CF!$B$187:$AZ$187,1,$A10))-180000)*0.45)))))+((E10 + 0.5*INDEX(Property_CF!$B$187:$AZ$187,1,$A10)))*0.02 -> 69243.912 | O10: =(IF((F10 + 0.5*INDEX(Property_CF!$B$187:$AZ$187,1,$A10))<=18200,0, IF((F10 + 0.5*INDEX(Property_CF!$B$187:$AZ$187,1,$A10))<=45000,((F10 + 0.5*INDEX(Property_CF!$B$187:$AZ$187,1,$A10))-18200)*0.19, IF((F10 + 0.5*INDEX(Property_CF!$B$187:$AZ$187,1,$A10))<=120000,5092+((F10 + 0.5*INDEX(Property_CF!$B$187:$AZ$187,1,$A10))-45000)*0.325, IF((F10 + 0.5*INDEX(Property_CF!$B$187:$AZ$187,1,$A10))<=180000,29467+((F10 + 0.5*INDEX(Property_CF!$B$187:$AZ$187,1,$A10))-120000)*0.37, 51667+((F10 + 0.5*INDEX(Property_CF!$B$187:$AZ$187,1,$A10))-180000)*0.45)))))+((F10 + 0.5*INDEX(Property_CF!$B$187:$AZ$187,1,$A10)))*0.02 -> 65483.912 | P10: {=E10+F10+INDEX(Property_CF!$C$187:$AZ$187,1,$A10)} -> 408289.17 | Q10: =Budget!$P$6 -> 76477.3 | R10: =SUM('Rental Tax & Gearing'!$H$6:$H$8) -> -11228.788 | S10: =IF($C10 < Scenarios!$K$7, (P10 + R10 - Q10), 0 ) -> 320583.08 | T10: =IF($C10 < Scenarios!$K$7, P10 - Budget!$P$6, 0) -> 331811.87 | U10: =U9*(1+Scenarios!$K$8) + IF(C10<Scenarios!$K$7, 'Superannuation (Inputs)'!$N$7, 0) -> 1642070 | V10: =V9*(1+Scenarios!$K$11) -> 2007094.6 | W10: =W9*(1+0.03) -> 758381.76 | X10: =SUM(U10:W10) -> 4407546.3 | Y10: =IF(C10>=Scenarios!$K$7, Profile!B13*(1+Scenarios!$K$10)^(C10-Scenarios!$K$7), 0) -> 0 | Z10: =X10-Y10 -> 4407546.3
A11: =ROW()-ROW($A$6)+1 -> 6 | B11: =B10+1 -> 2031 | C11: =C10+1 -> 53 | D11: =D10+1 -> 46 | E11: =IF( $C11 < Scenarios!$K$7, _xlfn.XLOOKUP($B11,'Income Schedule'!$A$5:$A$60,'Income Schedule'!$B$5:$B$60,0), IF( $C11 = Scenarios!$K$7, _xlfn.XLOOKUP($B11,'Income Schedule'!$A$5:$A$60,'Income Schedule'!$B$5:$B$60,0) * (1-Profile!$B$20), 0 ) ) -> 180000 | F11: =IF( $C11 < (Scenarios!$K$15 + (Profile!$B$6-Profile!$B$7)), _xlfn.XLOOKUP($B11,'Income Schedule'!$A$5:$A$60,'Income Schedule'!$C$5:$C$60,0), IF( $C11 = (Scenarios!$K$15 + (Profile!$B$6-Profile!$B$7)), _xlfn.XLOOKUP($B11,'Income Schedule'!$A$5:$A$60,'Income Schedule'!$C$5:$C$60,0) * (1-Profile!$B$21), 0 ) ) -> 172000 | G11: =IF( $C11 < Scenarios!$K$7, IF('Superannuation (Inputs)'!$I$6="Fixed", 'Superannuation (Inputs)'!$C$6, 'Superannuation (Inputs)'!$J$6 ), IF( $C11 = Scenarios!$K$7, IF('Superannuation (Inputs)'!$I$6="Fixed", 'Superannuation (Inputs)'!$C$6*(1-Profile!$B$20), 'Superannuation (Inputs)'!$J$6 ), 0 ) ) -> 5400 | H11: =G11 * 'Superannuation (Inputs)'!$H$6 -> 810 | I11: =IF( $C11 < (Scenarios!$K$15 + (Profile!$B$6-Profile!$B$7)), IF('Superannuation (Inputs)'!$I$7="Fixed", 'Superannuation (Inputs)'!$C$7, 'Superannuation (Inputs)'!$J$7 ), IF( $C11 = (Scenarios!$K$15 + (Profile!$B$6-Profile!$B$7)), IF('Superannuation (Inputs)'!$I$7="Fixed", 'Superannuation (Inputs)'!$C$7*(1-Profile!$B$21), 'Superannuation (Inputs)'!$J$7 ), 0 ) ) -> 25564 | J11: =I11 * 'Superannuation (Inputs)'!$H$7 -> 3834.6 | K11: =K10*(1+Scenarios!$K$8) + G11-H11 -> 897508.93 | L11: =L10*(1+Scenarios!$K$8) + H11-I11 -> 478338.78 | M11: =K11+L11 -> 1375847.7 | N11: =(IF((E11 + 0.5*INDEX(Property_CF!$B$187:$AZ$187,1,$A11))<=18200,0, IF((E11 + 0.5*INDEX(Property_CF!$B$187:$AZ$187,1,$A11))<=45000,((E11 + 0.5*INDEX(Property_CF!$B$187:$AZ$187,1,$A11))-18200)*0.19, IF((E11 + 0.5*INDEX(Property_CF!$B$187:$AZ$187,1,$A11))<=120000,5092+((E11 + 0.5*INDEX(Property_CF!$B$187:$AZ$187,1,$A11))-45000)*0.325, IF((E11 + 0.5*INDEX(Property_CF!$B$187:$AZ$187,1,$A11))<=180000,29467+((E11 + 0.5*INDEX(Property_CF!$B$187:$AZ$187,1,$A11))-120000)*0.37, 51667+((E11 + 0.5*INDEX(Property_CF!$B$187:$AZ$187,1,$A11))-180000)*0.45)))))+((E11 + 0.5*INDEX(Property_CF!$B$187:$AZ$187,1,$A11)))*0.02 -> 68494.955 | O11: =(IF((F11 + 0.5*INDEX(Property_CF!$B$187:$AZ$187,1,$A11))<=18200,0, IF((F11 + 0.5*INDEX(Property_CF!$B$187:$AZ$187,1,$A11))<=45000,((F11 + 0.5*INDEX(Property_CF!$B$187:$AZ$187,1,$A11))-18200)*0.19, IF((F11 + 0.5*INDEX(Property_CF!$B$187:$AZ$187,1,$A11))<=120000,5092+((F11 + 0.5*INDEX(Property_CF!$B$187:$AZ$187,1,$A11))-45000)*0.325, IF((F11 + 0.5*INDEX(Property_CF!$B$187:$AZ$187,1,$A11))<=180000,29467+((F11 + 0.5*INDEX(Property_CF!$B$187:$AZ$187,1,$A11))-120000)*0.37, 51667+((F11 + 0.5*INDEX(Property_CF!$B$187:$AZ$187,1,$A11))-180000)*0.45)))))+((F11 + 0.5*INDEX(Property_CF!$B$187:$AZ$187,1,$A11)))*0.02 -> 64734.955 | P11: {=E11+F11+INDEX(Property_CF!$C$187:$AZ$187,1,$A11)} -> 417350.87 | Q11: =Budget!$P$6 -> 76477.3 | R11: =SUM('Rental Tax & Gearing'!$H$6:$H$8) -> -11228.788 | S11: =IF($C11 < Scenarios!$K$7, (P11 + R11 - Q11), 0 ) -> 329644.78 | T11: =IF($C11 < Scenarios!$K$7, P11 - Budget!$P$6, 0) -> 340873.57 | U11: =U10*(1+Scenarios!$K$8) + IF(C11<Scenarios!$K$7, 'Superannuation (Inputs)'!$N$7, 0) -> 1803804.5 | V11: =V10*(1+Scenarios!$K$11) -> 2097413.8 | W11: =W10*(1+0.03) -> 781133.22 | X11: =SUM(U11:W11) -> 4682351.6 | Y11: =IF(C11>=Scenarios!$K$7, Profile!B14*(1+Scenarios!$K$10)^(C11-Scenarios!$K$7), 0) -> 0 | Z11: =X11-Y11 -> 4682351.6
A12: =ROW()-ROW($A$6)+1 -> 7 | B12: =B11+1 -> 2032 | C12: =C11+1 -> 54 | D12: =D11+1 -> 47 | E12: =IF( $C12 < Scenarios!$K$7, _xlfn.XLOOKUP($B12,'Income Schedule'!$A$5:$A$60,'Income Schedule'!$B$5:$B$60,0), IF( $C12 = Scenarios!$K$7, _xlfn.XLOOKUP($B12,'Income Schedule'!$A$5:$A$60,'Income Schedule'!$B$5:$B$60,0) * (1-Profile!$B$20), 0 ) ) -> 180000 | F12: =IF( $C12 < (Scenarios!$K$15 + (Profile!$B$6-Profile!$B$7)), _xlfn.XLOOKUP($B12,'Income Schedule'!$A$5:$A$60,'Income Schedule'!$C$5:$C$60,0), IF( $C12 = (Scenarios!$K$15 + (Profile!$B$6-Profile!$B$7)), _xlfn.XLOOKUP($B12,'Income Schedule'!$A$5:$A$60,'Income Schedule'!$C$5:$C$60,0) * (1-Profile!$B$21), 0 ) ) -> 172000 | G12: =IF( $C12 < Scenarios!$K$7, IF('Superannuation (Inputs)'!$I$6="Fixed", 'Superannuation (Inputs)'!$C$6, 'Superannuation (Inputs)'!$J$6 ), IF( $C12 = Scenarios!$K$7, IF('Superannuation (Inputs)'!$I$6="Fixed", 'Superannuation (Inputs)'!$C$6*(1-Profile!$B$20), 'Superannuation (Inputs)'!$J$6 ), 0 ) ) -> 5400 | H12: =G12 * 'Superannuation (Inputs)'!$H$6 -> 810 | I12: =IF( $C12 < (Scenarios!$K$15 + (Profile!$B$6-Profile!$B$7)), IF('Superannuation (Inputs)'!$I$7="Fixed", 'Superannuation (Inputs)'!$C$7, 'Superannuation (Inputs)'!$J$7 ), IF( $C12 = (Scenarios!$K$15 + (Profile!$B$6-Profile!$B$7)), IF('Superannuation (Inputs)'!$I$7="Fixed", 'Superannuation (Inputs)'!$C$7*(1-Profile!$B$21), 'Superannuation (Inputs)'!$J$7 ), 0 ) ) -> 25564 | J12: =I12 * 'Superannuation (Inputs)'!$H$7 -> 3834.6 | K12: =K11*(1+Scenarios!$K$8) + G12-H12 -> 960437.01 | L12: =L11*(1+Scenarios!$K$8) + H12-I12 -> 484676.8 | M12: =K12+L12 -> 1445113.8 | N12: =(IF((E12 + 0.5*INDEX(Property_CF!$B$187:$AZ$187,1,$A12))<=18200,0, IF((E12 + 0.5*INDEX(Property_CF!$B$187:$AZ$187,1,$A12))<=45000,((E12 + 0.5*INDEX(Property_CF!$B$187:$AZ$187,1,$A12))-18200)*0.19, IF((E12 + 0.5*INDEX(Property_CF!$B$187:$AZ$187,1,$A12))<=120000,5092+((E12 + 0.5*INDEX(Property_CF!$B$187:$AZ$187,1,$A12))-45000)*0.325, IF((E12 + 0.5*INDEX(Property_CF!$B$187:$AZ$187,1,$A12))<=180000,29467+((E12 + 0.5*INDEX(Property_CF!$B$187:$AZ$187,1,$A12))-120000)*0.37, 51667+((E12 + 0.5*INDEX(Property_CF!$B$187:$AZ$187,1,$A12))-180000)*0.45)))))+((E12 + 0.5*INDEX(Property_CF!$B$187:$AZ$187,1,$A12)))*0.02 -> 70624.454 | O12: =(IF((F12 + 0.5*INDEX(Property_CF!$B$187:$AZ$187,1,$A12))<=18200,0, IF((F12 + 0.5*INDEX(Property_CF!$B$187:$AZ$187,1,$A12))<=45000,((F12 + 0.5*INDEX(Property_CF!$B$187:$AZ$187,1,$A12))-18200)*0.19, IF((F12 + 0.5*INDEX(Property_CF!$B$187:$AZ$187,1,$A12))<=120000,5092+((F12 + 0.5*INDEX(Property_CF!$B$187:$AZ$187,1,$A12))-45000)*0.325, IF((F12 + 0.5*INDEX(Property_CF!$B$187:$AZ$187,1,$A12))<=180000,29467+((F12 + 0.5*INDEX(Property_CF!$B$187:$AZ$187,1,$A12))-120000)*0.37, 51667+((F12 + 0.5*INDEX(Property_CF!$B$187:$AZ$187,1,$A12))-180000)*0.45)))))+((F12 + 0.5*INDEX(Property_CF!$B$187:$AZ$187,1,$A12)))*0.02 -> 66864.454 | P12: {=E12+F12+INDEX(Property_CF!$C$187:$AZ$187,1,$A12)} -> 422811.48 | Q12: =Budget!$P$6 -> 76477.3 | R12: =SUM('Rental Tax & Gearing'!$H$6:$H$8) -> -11228.788 | S12: =IF($C12 < Scenarios!$K$7, (P12 + R12 - Q12), 0 ) -> 335105.4 | T12: =IF($C12 < Scenarios!$K$7, P12 - Budget!$P$6, 0) -> 346334.18 | U12: =U11*(1+Scenarios!$K$8) + IF(C12<Scenarios!$K$7, 'Superannuation (Inputs)'!$N$7, 0) -> 1976051.8 | V12: =V11*(1+Scenarios!$K$11) -> 2191797.4 | W12: =W11*(1+0.03) -> 804567.21 | X12: =SUM(U12:W12) -> 4972416.5 | Y12: =IF(C12>=Scenarios!$K$7, Profile!B15*(1+Scenarios!$K$10)^(C12-Scenarios!$K$7), 0) -> 0 | Z12: =X12-Y12 -> 4972416.5
A13: =ROW()-ROW($A$6)+1 -> 8 | B13: =B12+1 -> 2033 | C13: =C12+1 -> 55 | D13: =D12+1 -> 48 | E13: =IF( $C13 < Scenarios!$K$7, _xlfn.XLOOKUP($B13,'Income Schedule'!$A$5:$A$60,'Income Schedule'!$B$5:$B$60,0), IF( $C13 = Scenarios!$K$7, _xlfn.XLOOKUP($B13,'Income Schedule'!$A$5:$A$60,'Income Schedule'!$B$5:$B$60,0) * (1-Profile!$B$20), 0 ) ) -> 180000 | F13: =IF( $C13 < (Scenarios!$K$15 + (Profile!$B$6-Profile!$B$7)), _xlfn.XLOOKUP($B13,'Income Schedule'!$A$5:$A$60,'Income Schedule'!$C$5:$C$60,0), IF( $C13 = (Scenarios!$K$15 + (Profile!$B$6-Profile!$B$7)), _xlfn.XLOOKUP($B13,'Income Schedule'!$A$5:$A$60,'Income Schedule'!$C$5:$C$60,0) * (1-Profile!$B$21), 0 ) ) -> 172000 | G13: =IF( $C13 < Scenarios!$K$7, IF('Superannuation (Inputs)'!$I$6="Fixed", 'Superannuation (Inputs)'!$C$6, 'Superannuation (Inputs)'!$J$6 ), IF( $C13 = Scenarios!$K$7, IF('Superannuation (Inputs)'!$I$6="Fixed", 'Superannuation (Inputs)'!$C$6*(1-Profile!$B$20), 'Superannuation (Inputs)'!$J$6 ), 0 ) ) -> 5400 | H13: =G13 * 'Superannuation (Inputs)'!$H$6 -> 810 | I13: =IF( $C13 < (Scenarios!$K$15 + (Profile!$B$6-Profile!$B$7)), IF('Superannuation (Inputs)'!$I$7="Fixed", 'Superannuation (Inputs)'!$C$7, 'Superannuation (Inputs)'!$J$7 ), IF( $C13 = (Scenarios!$K$15 + (Profile!$B$6-Profile!$B$7)), IF('Superannuation (Inputs)'!$I$7="Fixed", 'Superannuation (Inputs)'!$C$7*(1-Profile!$B$21), 'Superannuation (Inputs)'!$J$7 ), 0 ) ) -> 25564 | J13: =I13 * 'Superannuation (Inputs)'!$H$7 -> 3834.6 | K13: =K12*(1+Scenarios!$K$8) + G13-H13 -> 1027455.4 | L13: =L12*(1+Scenarios!$K$8) + H13-I13 -> 491426.8 | M13: =K13+L13 -> 1518882.2 | N13: =(IF((E13 + 0.5*INDEX(Property_CF!$B$187:$AZ$187,1,$A13))<=18200,0, IF((E13 + 0.5*INDEX(Property_CF!$B$187:$AZ$187,1,$A13))<=45000,((E13 + 0.5*INDEX(Property_CF!$B$187:$AZ$187,1,$A13))-18200)*0.19, IF((E13 + 0.5*INDEX(Property_CF!$B$187:$AZ$187,1,$A13))<=120000,5092+((E13 + 0.5*INDEX(Property_CF!$B$187:$AZ$187,1,$A13))-45000)*0.325, IF((E13 + 0.5*INDEX(Property_CF!$B$187:$AZ$187,1,$A13))<=180000,29467+((E13 + 0.5*INDEX(Property_CF!$B$187:$AZ$187,1,$A13))-120000)*0.37, 51667+((E13 + 0.5*INDEX(Property_CF!$B$187:$AZ$187,1,$A13))-180000)*0.45)))))+((E13 + 0.5*INDEX(Property_CF!$B$187:$AZ$187,1,$A13)))*0.02 -> 71907.698 | O13: =(IF((F13 + 0.5*INDEX(Property_CF!$B$187:$AZ$187,1,$A13))<=18200,0, IF((F13 + 0.5*INDEX(Property_CF!$B$187:$AZ$187,1,$A13))<=45000,((F13 + 0.5*INDEX(Property_CF!$B$187:$AZ$187,1,$A13))-18200)*0.19, IF((F13 + 0.5*INDEX(Property_CF!$B$187:$AZ$187,1,$A13))<=120000,5092+((F13 + 0.5*INDEX(Property_CF!$B$187:$AZ$187,1,$A13))-45000)*0.325, IF((F13 + 0.5*INDEX(Property_CF!$B$187:$AZ$187,1,$A13))<=180000,29467+((F13 + 0.5*INDEX(Property_CF!$B$187:$AZ$187,1,$A13))-120000)*0.37, 51667+((F13 + 0.5*INDEX(Property_CF!$B$187:$AZ$187,1,$A13))-180000)*0.45)))))+((F13 + 0.5*INDEX(Property_CF!$B$187:$AZ$187,1,$A13)))*0.02 -> 68147.698 | P13: {=E13+F13+INDEX(Property_CF!$C$187:$AZ$187,1,$A13)} -> 428497.15 | Q13: =Budget!$P$6 -> 76477.3 | R13: =SUM('Rental Tax & Gearing'!$H$6:$H$8) -> -11228.788 | S13: =IF($C13 < Scenarios!$K$7, (P13 + R13 - Q13), 0 ) -> 340791.06 | T13: =IF($C13 < Scenarios!$K$7, P13 - Budget!$P$6, 0) -> 352019.85 | U13: =U12*(1+Scenarios!$K$8) + IF(C13<Scenarios!$K$7, 'Superannuation (Inputs)'!$N$7, 0) -> 2159495.2 | V13: =V12*(1+Scenarios!$K$11) -> 2290428.3 | W13: =W12*(1+0.03) -> 828704.23 | X13: =SUM(U13:W13) -> 5278627.8 | Y13: =IF(C13>=Scenarios!$K$7, Profile!B16*(1+Scenarios!$K$10)^(C13-Scenarios!$K$7), 0) -> 0 | Z13: =X13-Y13 -> 5278627.8
A14: =ROW()-ROW($A$6)+1 -> 9 | B14: =B13+1 -> 2034 | C14: =C13+1 -> 56 | D14: =D13+1 -> 49 | E14: =IF( $C14 < Scenarios!$K$7, _xlfn.XLOOKUP($B14,'Income Schedule'!$A$5:$A$60,'Income Schedule'!$B$5:$B$60,0), IF( $C14 = Scenarios!$K$7, _xlfn.XLOOKUP($B14,'Income Schedule'!$A$5:$A$60,'Income Schedule'!$B$5:$B$60,0) * (1-Profile!$B$20), 0 ) ) -> 180000 | F14: =IF( $C14 < (Scenarios!$K$15 + (Profile!$B$6-Profile!$B$7)), _xlfn.XLOOKUP($B14,'Income Schedule'!$A$5:$A$60,'Income Schedule'!$C$5:$C$60,0), IF( $C14 = (Scenarios!$K$15 + (Profile!$B$6-Profile!$B$7)), _xlfn.XLOOKUP($B14,'Income Schedule'!$A$5:$A$60,'Income Schedule'!$C$5:$C$60,0) * (1-Profile!$B$21), 0 ) ) -> 172000 | G14: =IF( $C14 < Scenarios!$K$7, IF('Superannuation (Inputs)'!$I$6="Fixed", 'Superannuation (Inputs)'!$C$6, 'Superannuation (Inputs)'!$J$6 ), IF( $C14 = Scenarios!$K$7, IF('Superannuation (Inputs)'!$I$6="Fixed", 'Superannuation (Inputs)'!$C$6*(1-Profile!$B$20), 'Superannuation (Inputs)'!$J$6 ), 0 ) ) -> 5400 | H14: =G14 * 'Superannuation (Inputs)'!$H$6 -> 810 | I14: =IF( $C14 < (Scenarios!$K$15 + (Profile!$B$6-Profile!$B$7)), IF('Superannuation (Inputs)'!$I$7="Fixed", 'Superannuation (Inputs)'!$C$7, 'Superannuation (Inputs)'!$J$7 ), IF( $C14 = (Scenarios!$K$15 + (Profile!$B$6-Profile!$B$7)), IF('Superannuation (Inputs)'!$I$7="Fixed", 'Superannuation (Inputs)'!$C$7*(1-Profile!$B$21), 'Superannuation (Inputs)'!$J$7 ), 0 ) ) -> 25564 | J14: =I14 * 'Superannuation (Inputs)'!$H$7 -> 3834.6 | K14: =K13*(1+Scenarios!$K$8) + G14-H14 -> 1098830 | L14: =L13*(1+Scenarios!$K$8) + H14-I14 -> 498615.54 | M14: =K14+L14 -> 1597445.6 | N14: =(IF((E14 + 0.5*INDEX(Property_CF!$B$187:$AZ$187,1,$A14))<=18200,0, IF((E14 + 0.5*INDEX(Property_CF!$B$187:$AZ$187,1,$A14))<=45000,((E14 + 0.5*INDEX(Property_CF!$B$187:$AZ$187,1,$A14))-18200)*0.19, IF((E14 + 0.5*INDEX(Property_CF!$B$187:$AZ$187,1,$A14))<=120000,5092+((E14 + 0.5*INDEX(Property_CF!$B$187:$AZ$187,1,$A14))-45000)*0.325, IF((E14 + 0.5*INDEX(Property_CF!$B$187:$AZ$187,1,$A14))<=180000,29467+((E14 + 0.5*INDEX(Property_CF!$B$187:$AZ$187,1,$A14))-120000)*0.37, 51667+((E14 + 0.5*INDEX(Property_CF!$B$187:$AZ$187,1,$A14))-180000)*0.45)))))+((E14 + 0.5*INDEX(Property_CF!$B$187:$AZ$187,1,$A14)))*0.02 -> 73243.829 | O14: =(IF((F14 + 0.5*INDEX(Property_CF!$B$187:$AZ$187,1,$A14))<=18200,0, IF((F14 + 0.5*INDEX(Property_CF!$B$187:$AZ$187,1,$A14))<=45000,((F14 + 0.5*INDEX(Property_CF!$B$187:$AZ$187,1,$A14))-18200)*0.19, IF((F14 + 0.5*INDEX(Property_CF!$B$187:$AZ$187,1,$A14))<=120000,5092+((F14 + 0.5*INDEX(Property_CF!$B$187:$AZ$187,1,$A14))-45000)*0.325, IF((F14 + 0.5*INDEX(Property_CF!$B$187:$AZ$187,1,$A14))<=180000,29467+((F14 + 0.5*INDEX(Property_CF!$B$187:$AZ$187,1,$A14))-120000)*0.37, 51667+((F14 + 0.5*INDEX(Property_CF!$B$187:$AZ$187,1,$A14))-180000)*0.45)))))+((F14 + 0.5*INDEX(Property_CF!$B$187:$AZ$187,1,$A14)))*0.02 -> 69483.829 | P14: {=E14+F14+INDEX(Property_CF!$C$187:$AZ$187,1,$A14)} -> 430033.07 | Q14: =Budget!$P$6 -> 76477.3 | R14: =SUM('Rental Tax & Gearing'!$H$6:$H$8) -> -11228.788 | S14: =IF($C14 < Scenarios!$K$7, (P14 + R14 - Q14), 0 ) -> 342326.98 | T14: =IF($C14 < Scenarios!$K$7, P14 - Budget!$P$6, 0) -> 353555.77 | U14: =U13*(1+Scenarios!$K$8) + IF(C14<Scenarios!$K$7, 'Superannuation (Inputs)'!$N$7, 0) -> 2354862.4 | V14: =V13*(1+Scenarios!$K$11) -> 2393497.6 | W14: =W13*(1+0.03) -> 853565.36 | X14: =SUM(U14:W14) -> 5601925.3 | Y14: =IF(C14>=Scenarios!$K$7, Profile!B17*(1+Scenarios!$K$10)^(C14-Scenarios!$K$7), 0) -> 0 | Z14: =X14-Y14 -> 5601925.3
A15: =ROW()-ROW($A$6)+1 -> 10 | B15: =B14+1 -> 2035 | C15: =C14+1 -> 57 | D15: =D14+1 -> 50 | E15: =IF( $C15 < Scenarios!$K$7, _xlfn.XLOOKUP($B15,'Income Schedule'!$A$5:$A$60,'Income Schedule'!$B$5:$B$60,0), IF( $C15 = Scenarios!$K$7, _xlfn.XLOOKUP($B15,'Income Schedule'!$A$5:$A$60,'Income Schedule'!$B$5:$B$60,0) * (1-Profile!$B$20), 0 ) ) -> 180000 | F15: =IF( $C15 < (Scenarios!$K$15 + (Profile!$B$6-Profile!$B$7)), _xlfn.XLOOKUP($B15,'Income Schedule'!$A$5:$A$60,'Income Schedule'!$C$5:$C$60,0), IF( $C15 = (Scenarios!$K$15 + (Profile!$B$6-Profile!$B$7)), _xlfn.XLOOKUP($B15,'Income Schedule'!$A$5:$A$60,'Income Schedule'!$C$5:$C$60,0) * (1-Profile!$B$21), 0 ) ) -> 172000 | G15: =IF( $C15 < Scenarios!$K$7, IF('Superannuation (Inputs)'!$I$6="Fixed", 'Superannuation (Inputs)'!$C$6, 'Superannuation (Inputs)'!$J$6 ), IF( $C15 = Scenarios!$K$7, IF('Superannuation (Inputs)'!$I$6="Fixed", 'Superannuation (Inputs)'!$C$6*(1-Profile!$B$20), 'Superannuation (Inputs)'!$J$6 ), 0 ) ) -> 5400 | H15: =G15 * 'Superannuation (Inputs)'!$H$6 -> 810 | I15: =IF( $C15 < (Scenarios!$K$15 + (Profile!$B$6-Profile!$B$7)), IF('Superannuation (Inputs)'!$I$7="Fixed", 'Superannuation (Inputs)'!$C$7, 'Superannuation (Inputs)'!$J$7 ), IF( $C15 = (Scenarios!$K$15 + (Profile!$B$6-Profile!$B$7)), IF('Superannuation (Inputs)'!$I$7="Fixed", 'Superannuation (Inputs)'!$C$7*(1-Profile!$B$21), 'Superannuation (Inputs)'!$J$7 ), 0 ) ) -> 25564 | J15: =I15 * 'Superannuation (Inputs)'!$H$7 -> 3834.6 | K15: =K14*(1+Scenarios!$K$8) + G15-H15 -> 1174844 | L15: =L14*(1+Scenarios!$K$8) + H15-I15 -> 506271.55 | M15: =K15+L15 -> 1681115.5 | N15: =(IF((E15 + 0.5*INDEX(Property_CF!$B$187:$AZ$187,1,$A15))<=18200,0, IF((E15 + 0.5*INDEX(Property_CF!$B$187:$AZ$187,1,$A15))<=45000,((E15 + 0.5*INDEX(Property_CF!$B$187:$AZ$187,1,$A15))-18200)*0.19, IF((E15 + 0.5*INDEX(Property_CF!$B$187:$AZ$187,1,$A15))<=120000,5092+((E15 + 0.5*INDEX(Property_CF!$B$187:$AZ$187,1,$A15))-45000)*0.325, IF((E15 + 0.5*INDEX(Property_CF!$B$187:$AZ$187,1,$A15))<=180000,29467+((E15 + 0.5*INDEX(Property_CF!$B$187:$AZ$187,1,$A15))-120000)*0.37, 51667+((E15 + 0.5*INDEX(Property_CF!$B$187:$AZ$187,1,$A15))-180000)*0.45)))))+((E15 + 0.5*INDEX(Property_CF!$B$187:$AZ$187,1,$A15)))*0.02 -> 73604.772 | O15: =(IF((F15 + 0.5*INDEX(Property_CF!$B$187:$AZ$187,1,$A15))<=18200,0, IF((F15 + 0.5*INDEX(Property_CF!$B$187:$AZ$187,1,$A15))<=45000,((F15 + 0.5*INDEX(Property_CF!$B$187:$AZ$187,1,$A15))-18200)*0.19, IF((F15 + 0.5*INDEX(Property_CF!$B$187:$AZ$187,1,$A15))<=120000,5092+((F15 + 0.5*INDEX(Property_CF!$B$187:$AZ$187,1,$A15))-45000)*0.325, IF((F15 + 0.5*INDEX(Property_CF!$B$187:$AZ$187,1,$A15))<=180000,29467+((F15 + 0.5*INDEX(Property_CF!$B$187:$AZ$187,1,$A15))-120000)*0.37, 51667+((F15 + 0.5*INDEX(Property_CF!$B$187:$AZ$187,1,$A15))-180000)*0.45)))))+((F15 + 0.5*INDEX(Property_CF!$B$187:$AZ$187,1,$A15)))*0.02 -> 69844.772 | P15: {=E15+F15+INDEX(Property_CF!$C$187:$AZ$187,1,$A15)} -> 440585.86 | Q15: =Budget!$P$6 -> 76477.3 | R15: =SUM('Rental Tax & Gearing'!$H$6:$H$8) -> -11228.788 | S15: =IF($C15 < Scenarios!$K$7, (P15 + R15 - Q15), 0 ) -> 352879.77 | T15: =IF($C15 < Scenarios!$K$7, P15 - Budget!$P$6, 0) -> 364108.56 | U15: =U14*(1+Scenarios!$K$8) + IF(C15<Scenarios!$K$7, 'Superannuation (Inputs)'!$N$7, 0) -> 2562928.5 | V15: =V14*(1+Scenarios!$K$11) -> 2501205 | W15: =W14*(1+0.03) -> 879172.32 | X15: =SUM(U15:W15) -> 5943305.8 | Y15: =IF(C15>=Scenarios!$K$7, Profile!B18*(1+Scenarios!$K$10)^(C15-Scenarios!$K$7), 0) -> 0 | Z15: =X15-Y15 -> 5943305.8
A16: =ROW()-ROW($A$6)+1 -> 11 | B16: =B15+1 -> 2036 | C16: =C15+1 -> 58 | D16: =D15+1 -> 51 | E16: =IF( $C16 < Scenarios!$K$7, _xlfn.XLOOKUP($B16,'Income Schedule'!$A$5:$A$60,'Income Schedule'!$B$5:$B$60,0), IF( $C16 = Scenarios!$K$7, _xlfn.XLOOKUP($B16,'Income Schedule'!$A$5:$A$60,'Income Schedule'!$B$5:$B$60,0) * (1-Profile!$B$20), 0 ) ) -> 180000 | F16: =IF( $C16 < (Scenarios!$K$15 + (Profile!$B$6-Profile!$B$7)), _xlfn.XLOOKUP($B16,'Income Schedule'!$A$5:$A$60,'Income Schedule'!$C$5:$C$60,0), IF( $C16 = (Scenarios!$K$15 + (Profile!$B$6-Profile!$B$7)), _xlfn.XLOOKUP($B16,'Income Schedule'!$A$5:$A$60,'Income Schedule'!$C$5:$C$60,0) * (1-Profile!$B$21), 0 ) ) -> 172000 | G16: =IF( $C16 < Scenarios!$K$7, IF('Superannuation (Inputs)'!$I$6="Fixed", 'Superannuation (Inputs)'!$C$6, 'Superannuation (Inputs)'!$J$6 ), IF( $C16 = Scenarios!$K$7, IF('Superannuation (Inputs)'!$I$6="Fixed", 'Superannuation (Inputs)'!$C$6*(1-Profile!$B$20), 'Superannuation (Inputs)'!$J$6 ), 0 ) ) -> 5400 | H16: =G16 * 'Superannuation (Inputs)'!$H$6 -> 810 | I16: =IF( $C16 < (Scenarios!$K$15 + (Profile!$B$6-Profile!$B$7)), IF('Superannuation (Inputs)'!$I$7="Fixed", 'Superannuation (Inputs)'!$C$7, 'Superannuation (Inputs)'!$J$7 ), IF( $C16 = (Scenarios!$K$15 + (Profile!$B$6-Profile!$B$7)), IF('Superannuation (Inputs)'!$I$7="Fixed", 'Superannuation (Inputs)'!$C$7*(1-Profile!$B$21), 'Superannuation (Inputs)'!$J$7 ), 0 ) ) -> 25564 | J16: =I16 * 'Superannuation (Inputs)'!$H$7 -> 3834.6 | K16: =K15*(1+Scenarios!$K$8) + G16-H16 -> 1255798.8 | L16: =L15*(1+Scenarios!$K$8) + H16-I16 -> 514425.2 | M16: =K16+L16 -> 1770224 | N16: =(IF((E16 + 0.5*INDEX(Property_CF!$B$187:$AZ$187,1,$A16))<=18200,0, IF((E16 + 0.5*INDEX(Property_CF!$B$187:$AZ$187,1,$A16))<=45000,((E16 + 0.5*INDEX(Property_CF!$B$187:$AZ$187,1,$A16))-18200)*0.19, IF((E16 + 0.5*INDEX(Property_CF!$B$187:$AZ$187,1,$A16))<=120000,5092+((E16 + 0.5*INDEX(Property_CF!$B$187:$AZ$187,1,$A16))-45000)*0.325, IF((E16 + 0.5*INDEX(Property_CF!$B$187:$AZ$187,1,$A16))<=180000,29467+((E16 + 0.5*INDEX(Property_CF!$B$187:$AZ$187,1,$A16))-120000)*0.37, 51667+((E16 + 0.5*INDEX(Property_CF!$B$187:$AZ$187,1,$A16))-180000)*0.45)))))+((E16 + 0.5*INDEX(Property_CF!$B$187:$AZ$187,1,$A16)))*0.02 -> 76084.677 | O16: =(IF((F16 + 0.5*INDEX(Property_CF!$B$187:$AZ$187,1,$A16))<=18200,0, IF((F16 + 0.5*INDEX(Property_CF!$B$187:$AZ$187,1,$A16))<=45000,((F16 + 0.5*INDEX(Property_CF!$B$187:$AZ$187,1,$A16))-18200)*0.19, IF((F16 + 0.5*INDEX(Property_CF!$B$187:$AZ$187,1,$A16))<=120000,5092+((F16 + 0.5*INDEX(Property_CF!$B$187:$AZ$187,1,$A16))-45000)*0.325, IF((F16 + 0.5*INDEX(Property_CF!$B$187:$AZ$187,1,$A16))<=180000,29467+((F16 + 0.5*INDEX(Property_CF!$B$187:$AZ$187,1,$A16))-120000)*0.37, 51667+((F16 + 0.5*INDEX(Property_CF!$B$187:$AZ$187,1,$A16))-180000)*0.45)))))+((F16 + 0.5*INDEX(Property_CF!$B$187:$AZ$187,1,$A16)))*0.02 -> 72324.677 | P16: {=E16+F16+INDEX(Property_CF!$C$187:$AZ$187,1,$A16)} -> 447009.8 | Q16: =Budget!$P$6 -> 76477.3 | R16: =SUM('Rental Tax & Gearing'!$H$6:$H$8) -> -11228.788 | S16: =IF($C16 < Scenarios!$K$7, (P16 + R16 - Q16), 0 ) -> 359303.71 | T16: =IF($C16 < Scenarios!$K$7, P16 - Budget!$P$6, 0) -> 370532.5 | U16: =U15*(1+Scenarios!$K$8) + IF(C16<Scenarios!$K$7, 'Superannuation (Inputs)'!$N$7, 0) -> 2784518.8 | V16: =V15*(1+Scenarios!$K$11) -> 2613759.2 | W16: =W15*(1+0.03) -> 905547.49 | X16: =SUM(U16:W16) -> 6303825.5 | Y16: =IF(C16>=Scenarios!$K$7, Profile!B19*(1+Scenarios!$K$10)^(C16-Scenarios!$K$7), 0) -> 0 | Z16: =X16-Y16 -> 6303825.5
A17: =ROW()-ROW($A$6)+1 -> 12 | B17: =B16+1 -> 2037 | C17: =C16+1 -> 59 | D17: =D16+1 -> 52 | E17: =IF( $C17 < Scenarios!$K$7, _xlfn.XLOOKUP($B17,'Income Schedule'!$A$5:$A$60,'Income Schedule'!$B$5:$B$60,0), IF( $C17 = Scenarios!$K$7, _xlfn.XLOOKUP($B17,'Income Schedule'!$A$5:$A$60,'Income Schedule'!$B$5:$B$60,0) * (1-Profile!$B$20), 0 ) ) -> 180000 | F17: =IF( $C17 < (Scenarios!$K$15 + (Profile!$B$6-Profile!$B$7)), _xlfn.XLOOKUP($B17,'Income Schedule'!$A$5:$A$60,'Income Schedule'!$C$5:$C$60,0), IF( $C17 = (Scenarios!$K$15 + (Profile!$B$6-Profile!$B$7)), _xlfn.XLOOKUP($B17,'Income Schedule'!$A$5:$A$60,'Income Schedule'!$C$5:$C$60,0) * (1-Profile!$B$21), 0 ) ) -> 172000 | G17: =IF( $C17 < Scenarios!$K$7, IF('Superannuation (Inputs)'!$I$6="Fixed", 'Superannuation (Inputs)'!$C$6, 'Superannuation (Inputs)'!$J$6 ), IF( $C17 = Scenarios!$K$7, IF('Superannuation (Inputs)'!$I$6="Fixed", 'Superannuation (Inputs)'!$C$6*(1-Profile!$B$20), 'Superannuation (Inputs)'!$J$6 ), 0 ) ) -> 5400 | H17: =G17 * 'Superannuation (Inputs)'!$H$6 -> 810 | I17: =IF( $C17 < (Scenarios!$K$15 + (Profile!$B$6-Profile!$B$7)), IF('Superannuation (Inputs)'!$I$7="Fixed", 'Superannuation (Inputs)'!$C$7, 'Superannuation (Inputs)'!$J$7 ), IF( $C17 = (Scenarios!$K$15 + (Profile!$B$6-Profile!$B$7)), IF('Superannuation (Inputs)'!$I$7="Fixed", 'Superannuation (Inputs)'!$C$7*(1-Profile!$B$21), 'Superannuation (Inputs)'!$J$7 ), 0 ) ) -> 25564 | J17: =I17 * 'Superannuation (Inputs)'!$H$7 -> 3834.6 | K17: =K16*(1+Scenarios!$K$8) + G17-H17 -> 1342015.8 | L17: =L16*(1+Scenarios!$K$8) + H17-I17 -> 523108.84 | M17: =K17+L17 -> 1865124.6 | N17: =(IF((E17 + 0.5*INDEX(Property_CF!$B$187:$AZ$187,1,$A17))<=18200,0, IF((E17 + 0.5*INDEX(Property_CF!$B$187:$AZ$187,1,$A17))<=45000,((E17 + 0.5*INDEX(Property_CF!$B$187:$AZ$187,1,$A17))-18200)*0.19, IF((E17 + 0.5*INDEX(Property_CF!$B$187:$AZ$187,1,$A17))<=120000,5092+((E17 + 0.5*INDEX(Property_CF!$B$187:$AZ$187,1,$A17))-45000)*0.325, IF((E17 + 0.5*INDEX(Property_CF!$B$187:$AZ$187,1,$A17))<=180000,29467+((E17 + 0.5*INDEX(Property_CF!$B$187:$AZ$187,1,$A17))-120000)*0.37, 51667+((E17 + 0.5*INDEX(Property_CF!$B$187:$AZ$187,1,$A17))-180000)*0.45)))))+((E17 + 0.5*INDEX(Property_CF!$B$187:$AZ$187,1,$A17)))*0.02 -> 77594.302 | O17: =(IF((F17 + 0.5*INDEX(Property_CF!$B$187:$AZ$187,1,$A17))<=18200,0, IF((F17 + 0.5*INDEX(Property_CF!$B$187:$AZ$187,1,$A17))<=45000,((F17 + 0.5*INDEX(Property_CF!$B$187:$AZ$187,1,$A17))-18200)*0.19, IF((F17 + 0.5*INDEX(Property_CF!$B$187:$AZ$187,1,$A17))<=120000,5092+((F17 + 0.5*INDEX(Property_CF!$B$187:$AZ$187,1,$A17))-45000)*0.325, IF((F17 + 0.5*INDEX(Property_CF!$B$187:$AZ$187,1,$A17))<=180000,29467+((F17 + 0.5*INDEX(Property_CF!$B$187:$AZ$187,1,$A17))-120000)*0.37, 51667+((F17 + 0.5*INDEX(Property_CF!$B$187:$AZ$187,1,$A17))-180000)*0.45)))))+((F17 + 0.5*INDEX(Property_CF!$B$187:$AZ$187,1,$A17)))*0.02 -> 73834.302 | P17: {=E17+F17+INDEX(Property_CF!$C$187:$AZ$187,1,$A17)} -> 453703.22 | Q17: =Budget!$P$6 -> 76477.3 | R17: =SUM('Rental Tax & Gearing'!$H$6:$H$8) -> -11228.788 | S17: =IF($C17 < Scenarios!$K$7, (P17 + R17 - Q17), 0 ) -> 365997.13 | T17: =IF($C17 < Scenarios!$K$7, P17 - Budget!$P$6, 0) -> 377225.92 | U17: =U16*(1+Scenarios!$K$8) + IF(C17<Scenarios!$K$7, 'Superannuation (Inputs)'!$N$7, 0) -> 3020512.5 | V17: =V16*(1+Scenarios!$K$11) -> 2731378.4 | W17: =W16*(1+0.03) -> 932713.91 | X17: =SUM(U17:W17) -> 6684604.8 | Y17: =IF(C17>=Scenarios!$K$7, Profile!B20*(1+Scenarios!$K$10)^(C17-Scenarios!$K$7), 0) -> 0 | Z17: =X17-Y17 -> 6684604.8
A18: =ROW()-ROW($A$6)+1 -> 13 | B18: =B17+1 -> 2038 | C18: =C17+1 -> 60 | D18: =D17+1 -> 53 | E18: =IF( $C18 < Scenarios!$K$7, _xlfn.XLOOKUP($B18,'Income Schedule'!$A$5:$A$60,'Income Schedule'!$B$5:$B$60,0), IF( $C18 = Scenarios!$K$7, _xlfn.XLOOKUP($B18,'Income Schedule'!$A$5:$A$60,'Income Schedule'!$B$5:$B$60,0) * (1-Profile!$B$20), 0 ) ) -> 180000 | F18: =IF( $C18 < (Scenarios!$K$15 + (Profile!$B$6-Profile!$B$7)), _xlfn.XLOOKUP($B18,'Income Schedule'!$A$5:$A$60,'Income Schedule'!$C$5:$C$60,0), IF( $C18 = (Scenarios!$K$15 + (Profile!$B$6-Profile!$B$7)), _xlfn.XLOOKUP($B18,'Income Schedule'!$A$5:$A$60,'Income Schedule'!$C$5:$C$60,0) * (1-Profile!$B$21), 0 ) ) -> 172000 | G18: =IF( $C18 < Scenarios!$K$7, IF('Superannuation (Inputs)'!$I$6="Fixed", 'Superannuation (Inputs)'!$C$6, 'Superannuation (Inputs)'!$J$6 ), IF( $C18 = Scenarios!$K$7, IF('Superannuation (Inputs)'!$I$6="Fixed", 'Superannuation (Inputs)'!$C$6*(1-Profile!$B$20), 'Superannuation (Inputs)'!$J$6 ), 0 ) ) -> 5400 | H18: =G18 * 'Superannuation (Inputs)'!$H$6 -> 810 | I18: =IF( $C18 < (Scenarios!$K$15 + (Profile!$B$6-Profile!$B$7)), IF('Superannuation (Inputs)'!$I$7="Fixed", 'Superannuation (Inputs)'!$C$7, 'Superannuation (Inputs)'!$J$7 ), IF( $C18 = (Scenarios!$K$15 + (Profile!$B$6-Profile!$B$7)), IF('Superannuation (Inputs)'!$I$7="Fixed", 'Superannuation (Inputs)'!$C$7*(1-Profile!$B$21), 'Superannuation (Inputs)'!$J$7 ), 0 ) ) -> 25564 | J18: =I18 * 'Superannuation (Inputs)'!$H$7 -> 3834.6 | K18: =K17*(1+Scenarios!$K$8) + G18-H18 -> 1433836.8 | L18: =L17*(1+Scenarios!$K$8) + H18-I18 -> 532356.91 | M18: =K18+L18 -> 1966193.7 | N18: =(IF((E18 + 0.5*INDEX(Property_CF!$B$187:$AZ$187,1,$A18))<=18200,0, IF((E18 + 0.5*INDEX(Property_CF!$B$187:$AZ$187,1,$A18))<=45000,((E18 + 0.5*INDEX(Property_CF!$B$187:$AZ$187,1,$A18))-18200)*0.19, IF((E18 + 0.5*INDEX(Property_CF!$B$187:$AZ$187,1,$A18))<=120000,5092+((E18 + 0.5*INDEX(Property_CF!$B$187:$AZ$187,1,$A18))-45000)*0.325, IF((E18 + 0.5*INDEX(Property_CF!$B$187:$AZ$187,1,$A18))<=180000,29467+((E18 + 0.5*INDEX(Property_CF!$B$187:$AZ$187,1,$A18))-120000)*0.37, 51667+((E18 + 0.5*INDEX(Property_CF!$B$187:$AZ$187,1,$A18))-180000)*0.45)))))+((E18 + 0.5*INDEX(Property_CF!$B$187:$AZ$187,1,$A18)))*0.02 -> 79167.257 | O18: =(IF((F18 + 0.5*INDEX(Property_CF!$B$187:$AZ$187,1,$A18))<=18200,0, IF((F18 + 0.5*INDEX(Property_CF!$B$187:$AZ$187,1,$A18))<=45000,((F18 + 0.5*INDEX(Property_CF!$B$187:$AZ$187,1,$A18))-18200)*0.19, IF((F18 + 0.5*INDEX(Property_CF!$B$187:$AZ$187,1,$A18))<=120000,5092+((F18 + 0.5*INDEX(Property_CF!$B$187:$AZ$187,1,$A18))-45000)*0.325, IF((F18 + 0.5*INDEX(Property_CF!$B$187:$AZ$187,1,$A18))<=180000,29467+((F18 + 0.5*INDEX(Property_CF!$B$187:$AZ$187,1,$A18))-120000)*0.37, 51667+((F18 + 0.5*INDEX(Property_CF!$B$187:$AZ$187,1,$A18))-180000)*0.45)))))+((F18 + 0.5*INDEX(Property_CF!$B$187:$AZ$187,1,$A18)))*0.02 -> 75407.257 | P18: {=E18+F18+INDEX(Property_CF!$C$187:$AZ$187,1,$A18)} -> 456292.04 | Q18: =Budget!$P$6 -> 76477.3 | R18: =SUM('Rental Tax & Gearing'!$H$6:$H$8) -> -11228.788 | S18: =IF($C18 < Scenarios!$K$7, (P18 + R18 - Q18), 0 ) -> 0 | T18: =IF($C18 < Scenarios!$K$7, P18 - Budget!$P$6, 0) -> 0 | U18: =U17*(1+Scenarios!$K$8) + IF(C18<Scenarios!$K$7, 'Superannuation (Inputs)'!$N$7, 0) -> 3216845.8 | V18: =V17*(1+Scenarios!$K$11) -> 2854290.4 | W18: =W17*(1+0.03) -> 960695.33 | X18: =SUM(U18:W18) -> 7031831.6 | Y18: =IF(C18>=Scenarios!$K$7, Profile!B21*(1+Scenarios!$K$10)^(C18-Scenarios!$K$7), 0) -> 0 | Z18: =X18-Y18 -> 7031831.6
A19: =ROW()-ROW($A$6)+1 -> 14 | B19: =B18+1 -> 2039 | C19: =C18+1 -> 61 | D19: =D18+1 -> 54 | E19: =IF( $C19 < Scenarios!$K$7, _xlfn.XLOOKUP($B19,'Income Schedule'!$A$5:$A$60,'Income Schedule'!$B$5:$B$60,0), IF( $C19 = Scenarios!$K$7, _xlfn.XLOOKUP($B19,'Income Schedule'!$A$5:$A$60,'Income Schedule'!$B$5:$B$60,0) * (1-Profile!$B$20), 0 ) ) -> 0 | F19: =IF( $C19 < (Scenarios!$K$15 + (Profile!$B$6-Profile!$B$7)), _xlfn.XLOOKUP($B19,'Income Schedule'!$A$5:$A$60,'Income Schedule'!$C$5:$C$60,0), IF( $C19 = (Scenarios!$K$15 + (Profile!$B$6-Profile!$B$7)), _xlfn.XLOOKUP($B19,'Income Schedule'!$A$5:$A$60,'Income Schedule'!$C$5:$C$60,0) * (1-Profile!$B$21), 0 ) ) -> 0 | G19: =IF( $C19 < Scenarios!$K$7, IF('Superannuation (Inputs)'!$I$6="Fixed", 'Superannuation (Inputs)'!$C$6, 'Superannuation (Inputs)'!$J$6 ), IF( $C19 = Scenarios!$K$7, IF('Superannuation (Inputs)'!$I$6="Fixed", 'Superannuation (Inputs)'!$C$6*(1-Profile!$B$20), 'Superannuation (Inputs)'!$J$6 ), 0 ) ) -> 0 | H19: =G19 * 'Superannuation (Inputs)'!$H$6 -> 0 | I19: =IF( $C19 < (Scenarios!$K$15 + (Profile!$B$6-Profile!$B$7)), IF('Superannuation (Inputs)'!$I$7="Fixed", 'Superannuation (Inputs)'!$C$7, 'Superannuation (Inputs)'!$J$7 ), IF( $C19 = (Scenarios!$K$15 + (Profile!$B$6-Profile!$B$7)), IF('Superannuation (Inputs)'!$I$7="Fixed", 'Superannuation (Inputs)'!$C$7*(1-Profile!$B$21), 'Superannuation (Inputs)'!$J$7 ), 0 ) ) -> 0 | J19: =I19 * 'Superannuation (Inputs)'!$H$7 -> 0 | K19: =K18*(1+Scenarios!$K$8) + G19-H19 -> 1527036.2 | L19: =L18*(1+Scenarios!$K$8) + H19-I19 -> 566960.11 | M19: =K19+L19 -> 2093996.3 | N19: =(IF((E19 + 0.5*INDEX(Property_CF!$B$187:$AZ$187,1,$A19))<=18200,0, IF((E19 + 0.5*INDEX(Property_CF!$B$187:$AZ$187,1,$A19))<=45000,((E19 + 0.5*INDEX(Property_CF!$B$187:$AZ$187,1,$A19))-18200)*0.19, IF((E19 + 0.5*INDEX(Property_CF!$B$187:$AZ$187,1,$A19))<=120000,5092+((E19 + 0.5*INDEX(Property_CF!$B$187:$AZ$187,1,$A19))-45000)*0.325, IF((E19 + 0.5*INDEX(Property_CF!$B$187:$AZ$187,1,$A19))<=180000,29467+((E19 + 0.5*INDEX(Property_CF!$B$187:$AZ$187,1,$A19))-120000)*0.37, 51667+((E19 + 0.5*INDEX(Property_CF!$B$187:$AZ$187,1,$A19))-180000)*0.45)))))+((E19 + 0.5*INDEX(Property_CF!$B$187:$AZ$187,1,$A19)))*0.02 -> 8457.3767 | O19: =(IF((F19 + 0.5*INDEX(Property_CF!$B$187:$AZ$187,1,$A19))<=18200,0, IF((F19 + 0.5*INDEX(Property_CF!$B$187:$AZ$187,1,$A19))<=45000,((F19 + 0.5*INDEX(Property_CF!$B$187:$AZ$187,1,$A19))-18200)*0.19, IF((F19 + 0.5*INDEX(Property_CF!$B$187:$AZ$187,1,$A19))<=120000,5092+((F19 + 0.5*INDEX(Property_CF!$B$187:$AZ$187,1,$A19))-45000)*0.325, IF((F19 + 0.5*INDEX(Property_CF!$B$187:$AZ$187,1,$A19))<=180000,29467+((F19 + 0.5*INDEX(Property_CF!$B$187:$AZ$187,1,$A19))-120000)*0.37, 51667+((F19 + 0.5*INDEX(Property_CF!$B$187:$AZ$187,1,$A19))-180000)*0.45)))))+((F19 + 0.5*INDEX(Property_CF!$B$187:$AZ$187,1,$A19)))*0.02 -> 8457.3767 | P19: {=E19+F19+INDEX(Property_CF!$C$187:$AZ$187,1,$A19)} -> 115947.45 | Q19: =Budget!$P$6 -> 76477.3 | R19: =SUM('Rental Tax & Gearing'!$H$6:$H$8) -> -11228.788 | S19: =IF($C19 < Scenarios!$K$7, (P19 + R19 - Q19), 0 ) -> 0 | T19: =IF($C19 < Scenarios!$K$7, P19 - Budget!$P$6, 0) -> 0 | U19: =U18*(1+Scenarios!$K$8) + IF(C19<Scenarios!$K$7, 'Superannuation (Inputs)'!$N$7, 0) -> 3425940.8 | V19: =V18*(1+Scenarios!$K$11) -> 2982733.5 | W19: =W18*(1+0.03) -> 989516.19 | X19: =SUM(U19:W19) -> 7398190.5 | Y19: =IF(C19>=Scenarios!$K$7, Profile!B22*(1+Scenarios!$K$10)^(C19-Scenarios!$K$7), 0) -> 0 | Z19: =X19-Y19 -> 7398190.5
